{
 "cells": [
  {
   "cell_type": "markdown",
   "metadata": {},
   "source": [
    "# Part I: Upload and Process Data\n",
    "\n",
    "In this part of the project, we will use the `main.py` script to set up the database and run scripts that read NHL data from AWS S3 buckets, process it, and insert it into the database.\n",
    "\n",
    "## Table of Contents\n",
    "1. [Introduction](#introduction)\n",
    "2. [Running the `main.py` Script](#running-the-mainpy-script)\n",
    "3. [Understanding the Logging](#understanding-the-logging)\n",
    "4. [Verifying the Processed Data](#verifying-the-processed-data)\n",
    "5. [Conclusion](#conclusion)\n"
   ]
  },
  {
   "cell_type": "markdown",
   "metadata": {},
   "source": [
    "## 1. Introduction\n",
    "\n",
    "This notebook will guide you through running the `main.py` script, which automates the process of downloading NHL data from AWS S3 buckets, processing it, and inserting it into the `hockey_stats` database. We will also review the log file generated during this process to ensure everything has executed correctly.\n"
   ]
  },
  {
   "cell_type": "markdown",
   "metadata": {},
   "source": [
    "## 2. Running the `main.py` Script\n",
    "\n",
    "The `main.py` script is the entry point for the data processing workflow. It runs a series of Python scripts that handle different parts of the data processing pipeline. These scripts are responsible for downloading data, processing it, and inserting it into the database.\n",
    "\n",
    "Below is the code from `main.py`:\n"
   ]
  },
  {
   "cell_type": "code",
   "execution_count": 1,
   "metadata": {},
   "outputs": [
    {
     "name": "stdout",
     "output_type": "stream",
     "text": [
      "Script game_processor.py failed with error: Traceback (most recent call last):\n",
      "  File \"/Users/ericwiniecke/.pyenv/versions/3.12.4/envs/cost_cup_env/lib/python3.12/site-packages/sqlalchemy/engine/base.py\", line 146, in __init__\n",
      "    self._dbapi_connection = engine.raw_connection()\n",
      "                             ^^^^^^^^^^^^^^^^^^^^^^^\n",
      "  File \"/Users/ericwiniecke/.pyenv/versions/3.12.4/envs/cost_cup_env/lib/python3.12/site-packages/sqlalchemy/engine/base.py\", line 3300, in raw_connection\n",
      "    return self.pool.connect()\n",
      "           ^^^^^^^^^^^^^^^^^^^\n",
      "  File \"/Users/ericwiniecke/.pyenv/versions/3.12.4/envs/cost_cup_env/lib/python3.12/site-packages/sqlalchemy/pool/base.py\", line 449, in connect\n",
      "    return _ConnectionFairy._checkout(self)\n",
      "           ^^^^^^^^^^^^^^^^^^^^^^^^^^^^^^^^\n",
      "  File \"/Users/ericwiniecke/.pyenv/versions/3.12.4/envs/cost_cup_env/lib/python3.12/site-packages/sqlalchemy/pool/base.py\", line 1263, in _checkout\n",
      "    fairy = _ConnectionRecord.checkout(pool)\n",
      "            ^^^^^^^^^^^^^^^^^^^^^^^^^^^^^^^^\n",
      "  File \"/Users/ericwiniecke/.pyenv/versions/3.12.4/envs/cost_cup_env/lib/python3.12/site-packages/sqlalchemy/pool/base.py\", line 712, in checkout\n",
      "    rec = pool._do_get()\n",
      "          ^^^^^^^^^^^^^^\n",
      "  File \"/Users/ericwiniecke/.pyenv/versions/3.12.4/envs/cost_cup_env/lib/python3.12/site-packages/sqlalchemy/pool/impl.py\", line 179, in _do_get\n",
      "    with util.safe_reraise():\n",
      "  File \"/Users/ericwiniecke/.pyenv/versions/3.12.4/envs/cost_cup_env/lib/python3.12/site-packages/sqlalchemy/util/langhelpers.py\", line 146, in __exit__\n",
      "    raise exc_value.with_traceback(exc_tb)\n",
      "  File \"/Users/ericwiniecke/.pyenv/versions/3.12.4/envs/cost_cup_env/lib/python3.12/site-packages/sqlalchemy/pool/impl.py\", line 177, in _do_get\n",
      "    return self._create_connection()\n",
      "           ^^^^^^^^^^^^^^^^^^^^^^^^^\n",
      "  File \"/Users/ericwiniecke/.pyenv/versions/3.12.4/envs/cost_cup_env/lib/python3.12/site-packages/sqlalchemy/pool/base.py\", line 390, in _create_connection\n",
      "    return _ConnectionRecord(self)\n",
      "           ^^^^^^^^^^^^^^^^^^^^^^^\n",
      "  File \"/Users/ericwiniecke/.pyenv/versions/3.12.4/envs/cost_cup_env/lib/python3.12/site-packages/sqlalchemy/pool/base.py\", line 674, in __init__\n",
      "    self.__connect()\n",
      "  File \"/Users/ericwiniecke/.pyenv/versions/3.12.4/envs/cost_cup_env/lib/python3.12/site-packages/sqlalchemy/pool/base.py\", line 900, in __connect\n",
      "    with util.safe_reraise():\n",
      "  File \"/Users/ericwiniecke/.pyenv/versions/3.12.4/envs/cost_cup_env/lib/python3.12/site-packages/sqlalchemy/util/langhelpers.py\", line 146, in __exit__\n",
      "    raise exc_value.with_traceback(exc_tb)\n",
      "  File \"/Users/ericwiniecke/.pyenv/versions/3.12.4/envs/cost_cup_env/lib/python3.12/site-packages/sqlalchemy/pool/base.py\", line 896, in __connect\n",
      "    self.dbapi_connection = connection = pool._invoke_creator(self)\n",
      "                                         ^^^^^^^^^^^^^^^^^^^^^^^^^^\n",
      "  File \"/Users/ericwiniecke/.pyenv/versions/3.12.4/envs/cost_cup_env/lib/python3.12/site-packages/sqlalchemy/engine/create.py\", line 643, in connect\n",
      "    return dialect.connect(*cargs, **cparams)\n",
      "           ^^^^^^^^^^^^^^^^^^^^^^^^^^^^^^^^^^\n",
      "  File \"/Users/ericwiniecke/.pyenv/versions/3.12.4/envs/cost_cup_env/lib/python3.12/site-packages/sqlalchemy/engine/default.py\", line 620, in connect\n",
      "    return self.loaded_dbapi.connect(*cargs, **cparams)\n",
      "           ^^^^^^^^^^^^^^^^^^^^^^^^^^^^^^^^^^^^^^^^^^^^\n",
      "  File \"/Users/ericwiniecke/.pyenv/versions/3.12.4/envs/cost_cup_env/lib/python3.12/site-packages/psycopg2/__init__.py\", line 122, in connect\n",
      "    conn = _connect(dsn, connection_factory=connection_factory, **kwasync)\n",
      "           ^^^^^^^^^^^^^^^^^^^^^^^^^^^^^^^^^^^^^^^^^^^^^^^^^^^^^^^^^^^^^^^\n",
      "psycopg2.OperationalError: connection to server at \"127.0.0.1\", port 5432 failed: FATAL:  role \"postgresql\" does not exist\n",
      "\n",
      "\n",
      "The above exception was the direct cause of the following exception:\n",
      "\n",
      "Traceback (most recent call last):\n",
      "  File \"/Users/ericwiniecke/Documents/github/cost_cup/game_processor.py\", line 282, in <module>\n",
      "    main()\n",
      "  File \"/Users/ericwiniecke/Documents/github/cost_cup/game_processor.py\", line 268, in main\n",
      "    create_table(engine)\n",
      "  File \"/Users/ericwiniecke/Documents/github/cost_cup/game_processor.py\", line 114, in create_table\n",
      "    metadata.create_all(engine)\n",
      "  File \"/Users/ericwiniecke/.pyenv/versions/3.12.4/envs/cost_cup_env/lib/python3.12/site-packages/sqlalchemy/sql/schema.py\", line 5871, in create_all\n",
      "    bind._run_ddl_visitor(\n",
      "  File \"/Users/ericwiniecke/.pyenv/versions/3.12.4/envs/cost_cup_env/lib/python3.12/site-packages/sqlalchemy/engine/base.py\", line 3250, in _run_ddl_visitor\n",
      "    with self.begin() as conn:\n",
      "  File \"/Users/ericwiniecke/.pyenv/versions/3.12.4/lib/python3.12/contextlib.py\", line 137, in __enter__\n",
      "    return next(self.gen)\n",
      "           ^^^^^^^^^^^^^^\n",
      "  File \"/Users/ericwiniecke/.pyenv/versions/3.12.4/envs/cost_cup_env/lib/python3.12/site-packages/sqlalchemy/engine/base.py\", line 3240, in begin\n",
      "    with self.connect() as conn:\n",
      "         ^^^^^^^^^^^^^^\n",
      "  File \"/Users/ericwiniecke/.pyenv/versions/3.12.4/envs/cost_cup_env/lib/python3.12/site-packages/sqlalchemy/engine/base.py\", line 3276, in connect\n",
      "    return self._connection_cls(self)\n",
      "           ^^^^^^^^^^^^^^^^^^^^^^^^^^\n",
      "  File \"/Users/ericwiniecke/.pyenv/versions/3.12.4/envs/cost_cup_env/lib/python3.12/site-packages/sqlalchemy/engine/base.py\", line 148, in __init__\n",
      "    Connection._handle_dbapi_exception_noconnection(\n",
      "  File \"/Users/ericwiniecke/.pyenv/versions/3.12.4/envs/cost_cup_env/lib/python3.12/site-packages/sqlalchemy/engine/base.py\", line 2440, in _handle_dbapi_exception_noconnection\n",
      "    raise sqlalchemy_exception.with_traceback(exc_info[2]) from e\n",
      "  File \"/Users/ericwiniecke/.pyenv/versions/3.12.4/envs/cost_cup_env/lib/python3.12/site-packages/sqlalchemy/engine/base.py\", line 146, in __init__\n",
      "    self._dbapi_connection = engine.raw_connection()\n",
      "                             ^^^^^^^^^^^^^^^^^^^^^^^\n",
      "  File \"/Users/ericwiniecke/.pyenv/versions/3.12.4/envs/cost_cup_env/lib/python3.12/site-packages/sqlalchemy/engine/base.py\", line 3300, in raw_connection\n",
      "    return self.pool.connect()\n",
      "           ^^^^^^^^^^^^^^^^^^^\n",
      "  File \"/Users/ericwiniecke/.pyenv/versions/3.12.4/envs/cost_cup_env/lib/python3.12/site-packages/sqlalchemy/pool/base.py\", line 449, in connect\n",
      "    return _ConnectionFairy._checkout(self)\n",
      "           ^^^^^^^^^^^^^^^^^^^^^^^^^^^^^^^^\n",
      "  File \"/Users/ericwiniecke/.pyenv/versions/3.12.4/envs/cost_cup_env/lib/python3.12/site-packages/sqlalchemy/pool/base.py\", line 1263, in _checkout\n",
      "    fairy = _ConnectionRecord.checkout(pool)\n",
      "            ^^^^^^^^^^^^^^^^^^^^^^^^^^^^^^^^\n",
      "  File \"/Users/ericwiniecke/.pyenv/versions/3.12.4/envs/cost_cup_env/lib/python3.12/site-packages/sqlalchemy/pool/base.py\", line 712, in checkout\n",
      "    rec = pool._do_get()\n",
      "          ^^^^^^^^^^^^^^\n",
      "  File \"/Users/ericwiniecke/.pyenv/versions/3.12.4/envs/cost_cup_env/lib/python3.12/site-packages/sqlalchemy/pool/impl.py\", line 179, in _do_get\n",
      "    with util.safe_reraise():\n",
      "  File \"/Users/ericwiniecke/.pyenv/versions/3.12.4/envs/cost_cup_env/lib/python3.12/site-packages/sqlalchemy/util/langhelpers.py\", line 146, in __exit__\n",
      "    raise exc_value.with_traceback(exc_tb)\n",
      "  File \"/Users/ericwiniecke/.pyenv/versions/3.12.4/envs/cost_cup_env/lib/python3.12/site-packages/sqlalchemy/pool/impl.py\", line 177, in _do_get\n",
      "    return self._create_connection()\n",
      "           ^^^^^^^^^^^^^^^^^^^^^^^^^\n",
      "  File \"/Users/ericwiniecke/.pyenv/versions/3.12.4/envs/cost_cup_env/lib/python3.12/site-packages/sqlalchemy/pool/base.py\", line 390, in _create_connection\n",
      "    return _ConnectionRecord(self)\n",
      "           ^^^^^^^^^^^^^^^^^^^^^^^\n",
      "  File \"/Users/ericwiniecke/.pyenv/versions/3.12.4/envs/cost_cup_env/lib/python3.12/site-packages/sqlalchemy/pool/base.py\", line 674, in __init__\n",
      "    self.__connect()\n",
      "  File \"/Users/ericwiniecke/.pyenv/versions/3.12.4/envs/cost_cup_env/lib/python3.12/site-packages/sqlalchemy/pool/base.py\", line 900, in __connect\n",
      "    with util.safe_reraise():\n",
      "  File \"/Users/ericwiniecke/.pyenv/versions/3.12.4/envs/cost_cup_env/lib/python3.12/site-packages/sqlalchemy/util/langhelpers.py\", line 146, in __exit__\n",
      "    raise exc_value.with_traceback(exc_tb)\n",
      "  File \"/Users/ericwiniecke/.pyenv/versions/3.12.4/envs/cost_cup_env/lib/python3.12/site-packages/sqlalchemy/pool/base.py\", line 896, in __connect\n",
      "    self.dbapi_connection = connection = pool._invoke_creator(self)\n",
      "                                         ^^^^^^^^^^^^^^^^^^^^^^^^^^\n",
      "  File \"/Users/ericwiniecke/.pyenv/versions/3.12.4/envs/cost_cup_env/lib/python3.12/site-packages/sqlalchemy/engine/create.py\", line 643, in connect\n",
      "    return dialect.connect(*cargs, **cparams)\n",
      "           ^^^^^^^^^^^^^^^^^^^^^^^^^^^^^^^^^^\n",
      "  File \"/Users/ericwiniecke/.pyenv/versions/3.12.4/envs/cost_cup_env/lib/python3.12/site-packages/sqlalchemy/engine/default.py\", line 620, in connect\n",
      "    return self.loaded_dbapi.connect(*cargs, **cparams)\n",
      "           ^^^^^^^^^^^^^^^^^^^^^^^^^^^^^^^^^^^^^^^^^^^^\n",
      "  File \"/Users/ericwiniecke/.pyenv/versions/3.12.4/envs/cost_cup_env/lib/python3.12/site-packages/psycopg2/__init__.py\", line 122, in connect\n",
      "    conn = _connect(dsn, connection_factory=connection_factory, **kwasync)\n",
      "           ^^^^^^^^^^^^^^^^^^^^^^^^^^^^^^^^^^^^^^^^^^^^^^^^^^^^^^^^^^^^^^^\n",
      "sqlalchemy.exc.OperationalError: (psycopg2.OperationalError) connection to server at \"127.0.0.1\", port 5432 failed: FATAL:  role \"postgresql\" does not exist\n",
      "\n",
      "(Background on this error at: https://sqlalche.me/e/20/e3q8)\n",
      "\n",
      "Script game_shifts_processor.py failed with error: Traceback (most recent call last):\n",
      "  File \"/Users/ericwiniecke/.pyenv/versions/3.12.4/envs/cost_cup_env/lib/python3.12/site-packages/sqlalchemy/engine/base.py\", line 146, in __init__\n",
      "    self._dbapi_connection = engine.raw_connection()\n",
      "                             ^^^^^^^^^^^^^^^^^^^^^^^\n",
      "  File \"/Users/ericwiniecke/.pyenv/versions/3.12.4/envs/cost_cup_env/lib/python3.12/site-packages/sqlalchemy/engine/base.py\", line 3300, in raw_connection\n",
      "    return self.pool.connect()\n",
      "           ^^^^^^^^^^^^^^^^^^^\n",
      "  File \"/Users/ericwiniecke/.pyenv/versions/3.12.4/envs/cost_cup_env/lib/python3.12/site-packages/sqlalchemy/pool/base.py\", line 449, in connect\n",
      "    return _ConnectionFairy._checkout(self)\n",
      "           ^^^^^^^^^^^^^^^^^^^^^^^^^^^^^^^^\n",
      "  File \"/Users/ericwiniecke/.pyenv/versions/3.12.4/envs/cost_cup_env/lib/python3.12/site-packages/sqlalchemy/pool/base.py\", line 1263, in _checkout\n",
      "    fairy = _ConnectionRecord.checkout(pool)\n",
      "            ^^^^^^^^^^^^^^^^^^^^^^^^^^^^^^^^\n",
      "  File \"/Users/ericwiniecke/.pyenv/versions/3.12.4/envs/cost_cup_env/lib/python3.12/site-packages/sqlalchemy/pool/base.py\", line 712, in checkout\n",
      "    rec = pool._do_get()\n",
      "          ^^^^^^^^^^^^^^\n",
      "  File \"/Users/ericwiniecke/.pyenv/versions/3.12.4/envs/cost_cup_env/lib/python3.12/site-packages/sqlalchemy/pool/impl.py\", line 179, in _do_get\n",
      "    with util.safe_reraise():\n",
      "  File \"/Users/ericwiniecke/.pyenv/versions/3.12.4/envs/cost_cup_env/lib/python3.12/site-packages/sqlalchemy/util/langhelpers.py\", line 146, in __exit__\n",
      "    raise exc_value.with_traceback(exc_tb)\n",
      "  File \"/Users/ericwiniecke/.pyenv/versions/3.12.4/envs/cost_cup_env/lib/python3.12/site-packages/sqlalchemy/pool/impl.py\", line 177, in _do_get\n",
      "    return self._create_connection()\n",
      "           ^^^^^^^^^^^^^^^^^^^^^^^^^\n",
      "  File \"/Users/ericwiniecke/.pyenv/versions/3.12.4/envs/cost_cup_env/lib/python3.12/site-packages/sqlalchemy/pool/base.py\", line 390, in _create_connection\n",
      "    return _ConnectionRecord(self)\n",
      "           ^^^^^^^^^^^^^^^^^^^^^^^\n",
      "  File \"/Users/ericwiniecke/.pyenv/versions/3.12.4/envs/cost_cup_env/lib/python3.12/site-packages/sqlalchemy/pool/base.py\", line 674, in __init__\n",
      "    self.__connect()\n",
      "  File \"/Users/ericwiniecke/.pyenv/versions/3.12.4/envs/cost_cup_env/lib/python3.12/site-packages/sqlalchemy/pool/base.py\", line 900, in __connect\n",
      "    with util.safe_reraise():\n",
      "  File \"/Users/ericwiniecke/.pyenv/versions/3.12.4/envs/cost_cup_env/lib/python3.12/site-packages/sqlalchemy/util/langhelpers.py\", line 146, in __exit__\n",
      "    raise exc_value.with_traceback(exc_tb)\n",
      "  File \"/Users/ericwiniecke/.pyenv/versions/3.12.4/envs/cost_cup_env/lib/python3.12/site-packages/sqlalchemy/pool/base.py\", line 896, in __connect\n",
      "    self.dbapi_connection = connection = pool._invoke_creator(self)\n",
      "                                         ^^^^^^^^^^^^^^^^^^^^^^^^^^\n",
      "  File \"/Users/ericwiniecke/.pyenv/versions/3.12.4/envs/cost_cup_env/lib/python3.12/site-packages/sqlalchemy/engine/create.py\", line 643, in connect\n",
      "    return dialect.connect(*cargs, **cparams)\n",
      "           ^^^^^^^^^^^^^^^^^^^^^^^^^^^^^^^^^^\n",
      "  File \"/Users/ericwiniecke/.pyenv/versions/3.12.4/envs/cost_cup_env/lib/python3.12/site-packages/sqlalchemy/engine/default.py\", line 620, in connect\n",
      "    return self.loaded_dbapi.connect(*cargs, **cparams)\n",
      "           ^^^^^^^^^^^^^^^^^^^^^^^^^^^^^^^^^^^^^^^^^^^^\n",
      "  File \"/Users/ericwiniecke/.pyenv/versions/3.12.4/envs/cost_cup_env/lib/python3.12/site-packages/psycopg2/__init__.py\", line 122, in connect\n",
      "    conn = _connect(dsn, connection_factory=connection_factory, **kwasync)\n",
      "           ^^^^^^^^^^^^^^^^^^^^^^^^^^^^^^^^^^^^^^^^^^^^^^^^^^^^^^^^^^^^^^^\n",
      "psycopg2.OperationalError: connection to server at \"127.0.0.1\", port 5432 failed: FATAL:  role \"postgresql\" does not exist\n",
      "\n",
      "\n",
      "The above exception was the direct cause of the following exception:\n",
      "\n",
      "Traceback (most recent call last):\n",
      "  File \"/Users/ericwiniecke/Documents/github/cost_cup/game_shifts_processor.py\", line 251, in <module>\n",
      "    main()\n",
      "  File \"/Users/ericwiniecke/Documents/github/cost_cup/game_shifts_processor.py\", line 235, in main\n",
      "    create_table(engine)\n",
      "  File \"/Users/ericwiniecke/Documents/github/cost_cup/game_shifts_processor.py\", line 92, in create_table\n",
      "    metadata.create_all(engine)\n",
      "  File \"/Users/ericwiniecke/.pyenv/versions/3.12.4/envs/cost_cup_env/lib/python3.12/site-packages/sqlalchemy/sql/schema.py\", line 5871, in create_all\n",
      "    bind._run_ddl_visitor(\n",
      "  File \"/Users/ericwiniecke/.pyenv/versions/3.12.4/envs/cost_cup_env/lib/python3.12/site-packages/sqlalchemy/engine/base.py\", line 3250, in _run_ddl_visitor\n",
      "    with self.begin() as conn:\n",
      "  File \"/Users/ericwiniecke/.pyenv/versions/3.12.4/lib/python3.12/contextlib.py\", line 137, in __enter__\n",
      "    return next(self.gen)\n",
      "           ^^^^^^^^^^^^^^\n",
      "  File \"/Users/ericwiniecke/.pyenv/versions/3.12.4/envs/cost_cup_env/lib/python3.12/site-packages/sqlalchemy/engine/base.py\", line 3240, in begin\n",
      "    with self.connect() as conn:\n",
      "         ^^^^^^^^^^^^^^\n",
      "  File \"/Users/ericwiniecke/.pyenv/versions/3.12.4/envs/cost_cup_env/lib/python3.12/site-packages/sqlalchemy/engine/base.py\", line 3276, in connect\n",
      "    return self._connection_cls(self)\n",
      "           ^^^^^^^^^^^^^^^^^^^^^^^^^^\n",
      "  File \"/Users/ericwiniecke/.pyenv/versions/3.12.4/envs/cost_cup_env/lib/python3.12/site-packages/sqlalchemy/engine/base.py\", line 148, in __init__\n",
      "    Connection._handle_dbapi_exception_noconnection(\n",
      "  File \"/Users/ericwiniecke/.pyenv/versions/3.12.4/envs/cost_cup_env/lib/python3.12/site-packages/sqlalchemy/engine/base.py\", line 2440, in _handle_dbapi_exception_noconnection\n",
      "    raise sqlalchemy_exception.with_traceback(exc_info[2]) from e\n",
      "  File \"/Users/ericwiniecke/.pyenv/versions/3.12.4/envs/cost_cup_env/lib/python3.12/site-packages/sqlalchemy/engine/base.py\", line 146, in __init__\n",
      "    self._dbapi_connection = engine.raw_connection()\n",
      "                             ^^^^^^^^^^^^^^^^^^^^^^^\n",
      "  File \"/Users/ericwiniecke/.pyenv/versions/3.12.4/envs/cost_cup_env/lib/python3.12/site-packages/sqlalchemy/engine/base.py\", line 3300, in raw_connection\n",
      "    return self.pool.connect()\n",
      "           ^^^^^^^^^^^^^^^^^^^\n",
      "  File \"/Users/ericwiniecke/.pyenv/versions/3.12.4/envs/cost_cup_env/lib/python3.12/site-packages/sqlalchemy/pool/base.py\", line 449, in connect\n",
      "    return _ConnectionFairy._checkout(self)\n",
      "           ^^^^^^^^^^^^^^^^^^^^^^^^^^^^^^^^\n",
      "  File \"/Users/ericwiniecke/.pyenv/versions/3.12.4/envs/cost_cup_env/lib/python3.12/site-packages/sqlalchemy/pool/base.py\", line 1263, in _checkout\n",
      "    fairy = _ConnectionRecord.checkout(pool)\n",
      "            ^^^^^^^^^^^^^^^^^^^^^^^^^^^^^^^^\n",
      "  File \"/Users/ericwiniecke/.pyenv/versions/3.12.4/envs/cost_cup_env/lib/python3.12/site-packages/sqlalchemy/pool/base.py\", line 712, in checkout\n",
      "    rec = pool._do_get()\n",
      "          ^^^^^^^^^^^^^^\n",
      "  File \"/Users/ericwiniecke/.pyenv/versions/3.12.4/envs/cost_cup_env/lib/python3.12/site-packages/sqlalchemy/pool/impl.py\", line 179, in _do_get\n",
      "    with util.safe_reraise():\n",
      "  File \"/Users/ericwiniecke/.pyenv/versions/3.12.4/envs/cost_cup_env/lib/python3.12/site-packages/sqlalchemy/util/langhelpers.py\", line 146, in __exit__\n",
      "    raise exc_value.with_traceback(exc_tb)\n",
      "  File \"/Users/ericwiniecke/.pyenv/versions/3.12.4/envs/cost_cup_env/lib/python3.12/site-packages/sqlalchemy/pool/impl.py\", line 177, in _do_get\n",
      "    return self._create_connection()\n",
      "           ^^^^^^^^^^^^^^^^^^^^^^^^^\n",
      "  File \"/Users/ericwiniecke/.pyenv/versions/3.12.4/envs/cost_cup_env/lib/python3.12/site-packages/sqlalchemy/pool/base.py\", line 390, in _create_connection\n",
      "    return _ConnectionRecord(self)\n",
      "           ^^^^^^^^^^^^^^^^^^^^^^^\n",
      "  File \"/Users/ericwiniecke/.pyenv/versions/3.12.4/envs/cost_cup_env/lib/python3.12/site-packages/sqlalchemy/pool/base.py\", line 674, in __init__\n",
      "    self.__connect()\n",
      "  File \"/Users/ericwiniecke/.pyenv/versions/3.12.4/envs/cost_cup_env/lib/python3.12/site-packages/sqlalchemy/pool/base.py\", line 900, in __connect\n",
      "    with util.safe_reraise():\n",
      "  File \"/Users/ericwiniecke/.pyenv/versions/3.12.4/envs/cost_cup_env/lib/python3.12/site-packages/sqlalchemy/util/langhelpers.py\", line 146, in __exit__\n",
      "    raise exc_value.with_traceback(exc_tb)\n",
      "  File \"/Users/ericwiniecke/.pyenv/versions/3.12.4/envs/cost_cup_env/lib/python3.12/site-packages/sqlalchemy/pool/base.py\", line 896, in __connect\n",
      "    self.dbapi_connection = connection = pool._invoke_creator(self)\n",
      "                                         ^^^^^^^^^^^^^^^^^^^^^^^^^^\n",
      "  File \"/Users/ericwiniecke/.pyenv/versions/3.12.4/envs/cost_cup_env/lib/python3.12/site-packages/sqlalchemy/engine/create.py\", line 643, in connect\n",
      "    return dialect.connect(*cargs, **cparams)\n",
      "           ^^^^^^^^^^^^^^^^^^^^^^^^^^^^^^^^^^\n",
      "  File \"/Users/ericwiniecke/.pyenv/versions/3.12.4/envs/cost_cup_env/lib/python3.12/site-packages/sqlalchemy/engine/default.py\", line 620, in connect\n",
      "    return self.loaded_dbapi.connect(*cargs, **cparams)\n",
      "           ^^^^^^^^^^^^^^^^^^^^^^^^^^^^^^^^^^^^^^^^^^^^\n",
      "  File \"/Users/ericwiniecke/.pyenv/versions/3.12.4/envs/cost_cup_env/lib/python3.12/site-packages/psycopg2/__init__.py\", line 122, in connect\n",
      "    conn = _connect(dsn, connection_factory=connection_factory, **kwasync)\n",
      "           ^^^^^^^^^^^^^^^^^^^^^^^^^^^^^^^^^^^^^^^^^^^^^^^^^^^^^^^^^^^^^^^\n",
      "sqlalchemy.exc.OperationalError: (psycopg2.OperationalError) connection to server at \"127.0.0.1\", port 5432 failed: FATAL:  role \"postgresql\" does not exist\n",
      "\n",
      "(Background on this error at: https://sqlalche.me/e/20/e3q8)\n",
      "\n",
      "Script game_skater_stats_processor.py failed with error: Traceback (most recent call last):\n",
      "  File \"/Users/ericwiniecke/.pyenv/versions/3.12.4/envs/cost_cup_env/lib/python3.12/site-packages/sqlalchemy/engine/base.py\", line 146, in __init__\n",
      "    self._dbapi_connection = engine.raw_connection()\n",
      "                             ^^^^^^^^^^^^^^^^^^^^^^^\n",
      "  File \"/Users/ericwiniecke/.pyenv/versions/3.12.4/envs/cost_cup_env/lib/python3.12/site-packages/sqlalchemy/engine/base.py\", line 3300, in raw_connection\n",
      "    return self.pool.connect()\n",
      "           ^^^^^^^^^^^^^^^^^^^\n",
      "  File \"/Users/ericwiniecke/.pyenv/versions/3.12.4/envs/cost_cup_env/lib/python3.12/site-packages/sqlalchemy/pool/base.py\", line 449, in connect\n",
      "    return _ConnectionFairy._checkout(self)\n",
      "           ^^^^^^^^^^^^^^^^^^^^^^^^^^^^^^^^\n",
      "  File \"/Users/ericwiniecke/.pyenv/versions/3.12.4/envs/cost_cup_env/lib/python3.12/site-packages/sqlalchemy/pool/base.py\", line 1263, in _checkout\n",
      "    fairy = _ConnectionRecord.checkout(pool)\n",
      "            ^^^^^^^^^^^^^^^^^^^^^^^^^^^^^^^^\n",
      "  File \"/Users/ericwiniecke/.pyenv/versions/3.12.4/envs/cost_cup_env/lib/python3.12/site-packages/sqlalchemy/pool/base.py\", line 712, in checkout\n",
      "    rec = pool._do_get()\n",
      "          ^^^^^^^^^^^^^^\n",
      "  File \"/Users/ericwiniecke/.pyenv/versions/3.12.4/envs/cost_cup_env/lib/python3.12/site-packages/sqlalchemy/pool/impl.py\", line 179, in _do_get\n",
      "    with util.safe_reraise():\n",
      "  File \"/Users/ericwiniecke/.pyenv/versions/3.12.4/envs/cost_cup_env/lib/python3.12/site-packages/sqlalchemy/util/langhelpers.py\", line 146, in __exit__\n",
      "    raise exc_value.with_traceback(exc_tb)\n",
      "  File \"/Users/ericwiniecke/.pyenv/versions/3.12.4/envs/cost_cup_env/lib/python3.12/site-packages/sqlalchemy/pool/impl.py\", line 177, in _do_get\n",
      "    return self._create_connection()\n",
      "           ^^^^^^^^^^^^^^^^^^^^^^^^^\n",
      "  File \"/Users/ericwiniecke/.pyenv/versions/3.12.4/envs/cost_cup_env/lib/python3.12/site-packages/sqlalchemy/pool/base.py\", line 390, in _create_connection\n",
      "    return _ConnectionRecord(self)\n",
      "           ^^^^^^^^^^^^^^^^^^^^^^^\n",
      "  File \"/Users/ericwiniecke/.pyenv/versions/3.12.4/envs/cost_cup_env/lib/python3.12/site-packages/sqlalchemy/pool/base.py\", line 674, in __init__\n",
      "    self.__connect()\n",
      "  File \"/Users/ericwiniecke/.pyenv/versions/3.12.4/envs/cost_cup_env/lib/python3.12/site-packages/sqlalchemy/pool/base.py\", line 900, in __connect\n",
      "    with util.safe_reraise():\n",
      "  File \"/Users/ericwiniecke/.pyenv/versions/3.12.4/envs/cost_cup_env/lib/python3.12/site-packages/sqlalchemy/util/langhelpers.py\", line 146, in __exit__\n",
      "    raise exc_value.with_traceback(exc_tb)\n",
      "  File \"/Users/ericwiniecke/.pyenv/versions/3.12.4/envs/cost_cup_env/lib/python3.12/site-packages/sqlalchemy/pool/base.py\", line 896, in __connect\n",
      "    self.dbapi_connection = connection = pool._invoke_creator(self)\n",
      "                                         ^^^^^^^^^^^^^^^^^^^^^^^^^^\n",
      "  File \"/Users/ericwiniecke/.pyenv/versions/3.12.4/envs/cost_cup_env/lib/python3.12/site-packages/sqlalchemy/engine/create.py\", line 643, in connect\n",
      "    return dialect.connect(*cargs, **cparams)\n",
      "           ^^^^^^^^^^^^^^^^^^^^^^^^^^^^^^^^^^\n",
      "  File \"/Users/ericwiniecke/.pyenv/versions/3.12.4/envs/cost_cup_env/lib/python3.12/site-packages/sqlalchemy/engine/default.py\", line 620, in connect\n",
      "    return self.loaded_dbapi.connect(*cargs, **cparams)\n",
      "           ^^^^^^^^^^^^^^^^^^^^^^^^^^^^^^^^^^^^^^^^^^^^\n",
      "  File \"/Users/ericwiniecke/.pyenv/versions/3.12.4/envs/cost_cup_env/lib/python3.12/site-packages/psycopg2/__init__.py\", line 122, in connect\n",
      "    conn = _connect(dsn, connection_factory=connection_factory, **kwasync)\n",
      "           ^^^^^^^^^^^^^^^^^^^^^^^^^^^^^^^^^^^^^^^^^^^^^^^^^^^^^^^^^^^^^^^\n",
      "psycopg2.OperationalError: connection to server at \"127.0.0.1\", port 5432 failed: FATAL:  role \"postgresql\" does not exist\n",
      "\n",
      "\n",
      "The above exception was the direct cause of the following exception:\n",
      "\n",
      "Traceback (most recent call last):\n",
      "  File \"/Users/ericwiniecke/Documents/github/cost_cup/game_skater_stats_processor.py\", line 342, in <module>\n",
      "    main()\n",
      "  File \"/Users/ericwiniecke/Documents/github/cost_cup/game_skater_stats_processor.py\", line 324, in main\n",
      "    create_table(engine)\n",
      "  File \"/Users/ericwiniecke/Documents/github/cost_cup/game_skater_stats_processor.py\", line 139, in create_table\n",
      "    metadata.create_all(engine)\n",
      "  File \"/Users/ericwiniecke/.pyenv/versions/3.12.4/envs/cost_cup_env/lib/python3.12/site-packages/sqlalchemy/sql/schema.py\", line 5871, in create_all\n",
      "    bind._run_ddl_visitor(\n",
      "  File \"/Users/ericwiniecke/.pyenv/versions/3.12.4/envs/cost_cup_env/lib/python3.12/site-packages/sqlalchemy/engine/base.py\", line 3250, in _run_ddl_visitor\n",
      "    with self.begin() as conn:\n",
      "  File \"/Users/ericwiniecke/.pyenv/versions/3.12.4/lib/python3.12/contextlib.py\", line 137, in __enter__\n",
      "    return next(self.gen)\n",
      "           ^^^^^^^^^^^^^^\n",
      "  File \"/Users/ericwiniecke/.pyenv/versions/3.12.4/envs/cost_cup_env/lib/python3.12/site-packages/sqlalchemy/engine/base.py\", line 3240, in begin\n",
      "    with self.connect() as conn:\n",
      "         ^^^^^^^^^^^^^^\n",
      "  File \"/Users/ericwiniecke/.pyenv/versions/3.12.4/envs/cost_cup_env/lib/python3.12/site-packages/sqlalchemy/engine/base.py\", line 3276, in connect\n",
      "    return self._connection_cls(self)\n",
      "           ^^^^^^^^^^^^^^^^^^^^^^^^^^\n",
      "  File \"/Users/ericwiniecke/.pyenv/versions/3.12.4/envs/cost_cup_env/lib/python3.12/site-packages/sqlalchemy/engine/base.py\", line 148, in __init__\n",
      "    Connection._handle_dbapi_exception_noconnection(\n",
      "  File \"/Users/ericwiniecke/.pyenv/versions/3.12.4/envs/cost_cup_env/lib/python3.12/site-packages/sqlalchemy/engine/base.py\", line 2440, in _handle_dbapi_exception_noconnection\n",
      "    raise sqlalchemy_exception.with_traceback(exc_info[2]) from e\n",
      "  File \"/Users/ericwiniecke/.pyenv/versions/3.12.4/envs/cost_cup_env/lib/python3.12/site-packages/sqlalchemy/engine/base.py\", line 146, in __init__\n",
      "    self._dbapi_connection = engine.raw_connection()\n",
      "                             ^^^^^^^^^^^^^^^^^^^^^^^\n",
      "  File \"/Users/ericwiniecke/.pyenv/versions/3.12.4/envs/cost_cup_env/lib/python3.12/site-packages/sqlalchemy/engine/base.py\", line 3300, in raw_connection\n",
      "    return self.pool.connect()\n",
      "           ^^^^^^^^^^^^^^^^^^^\n",
      "  File \"/Users/ericwiniecke/.pyenv/versions/3.12.4/envs/cost_cup_env/lib/python3.12/site-packages/sqlalchemy/pool/base.py\", line 449, in connect\n",
      "    return _ConnectionFairy._checkout(self)\n",
      "           ^^^^^^^^^^^^^^^^^^^^^^^^^^^^^^^^\n",
      "  File \"/Users/ericwiniecke/.pyenv/versions/3.12.4/envs/cost_cup_env/lib/python3.12/site-packages/sqlalchemy/pool/base.py\", line 1263, in _checkout\n",
      "    fairy = _ConnectionRecord.checkout(pool)\n",
      "            ^^^^^^^^^^^^^^^^^^^^^^^^^^^^^^^^\n",
      "  File \"/Users/ericwiniecke/.pyenv/versions/3.12.4/envs/cost_cup_env/lib/python3.12/site-packages/sqlalchemy/pool/base.py\", line 712, in checkout\n",
      "    rec = pool._do_get()\n",
      "          ^^^^^^^^^^^^^^\n",
      "  File \"/Users/ericwiniecke/.pyenv/versions/3.12.4/envs/cost_cup_env/lib/python3.12/site-packages/sqlalchemy/pool/impl.py\", line 179, in _do_get\n",
      "    with util.safe_reraise():\n",
      "  File \"/Users/ericwiniecke/.pyenv/versions/3.12.4/envs/cost_cup_env/lib/python3.12/site-packages/sqlalchemy/util/langhelpers.py\", line 146, in __exit__\n",
      "    raise exc_value.with_traceback(exc_tb)\n",
      "  File \"/Users/ericwiniecke/.pyenv/versions/3.12.4/envs/cost_cup_env/lib/python3.12/site-packages/sqlalchemy/pool/impl.py\", line 177, in _do_get\n",
      "    return self._create_connection()\n",
      "           ^^^^^^^^^^^^^^^^^^^^^^^^^\n",
      "  File \"/Users/ericwiniecke/.pyenv/versions/3.12.4/envs/cost_cup_env/lib/python3.12/site-packages/sqlalchemy/pool/base.py\", line 390, in _create_connection\n",
      "    return _ConnectionRecord(self)\n",
      "           ^^^^^^^^^^^^^^^^^^^^^^^\n",
      "  File \"/Users/ericwiniecke/.pyenv/versions/3.12.4/envs/cost_cup_env/lib/python3.12/site-packages/sqlalchemy/pool/base.py\", line 674, in __init__\n",
      "    self.__connect()\n",
      "  File \"/Users/ericwiniecke/.pyenv/versions/3.12.4/envs/cost_cup_env/lib/python3.12/site-packages/sqlalchemy/pool/base.py\", line 900, in __connect\n",
      "    with util.safe_reraise():\n",
      "  File \"/Users/ericwiniecke/.pyenv/versions/3.12.4/envs/cost_cup_env/lib/python3.12/site-packages/sqlalchemy/util/langhelpers.py\", line 146, in __exit__\n",
      "    raise exc_value.with_traceback(exc_tb)\n",
      "  File \"/Users/ericwiniecke/.pyenv/versions/3.12.4/envs/cost_cup_env/lib/python3.12/site-packages/sqlalchemy/pool/base.py\", line 896, in __connect\n",
      "    self.dbapi_connection = connection = pool._invoke_creator(self)\n",
      "                                         ^^^^^^^^^^^^^^^^^^^^^^^^^^\n",
      "  File \"/Users/ericwiniecke/.pyenv/versions/3.12.4/envs/cost_cup_env/lib/python3.12/site-packages/sqlalchemy/engine/create.py\", line 643, in connect\n",
      "    return dialect.connect(*cargs, **cparams)\n",
      "           ^^^^^^^^^^^^^^^^^^^^^^^^^^^^^^^^^^\n",
      "  File \"/Users/ericwiniecke/.pyenv/versions/3.12.4/envs/cost_cup_env/lib/python3.12/site-packages/sqlalchemy/engine/default.py\", line 620, in connect\n",
      "    return self.loaded_dbapi.connect(*cargs, **cparams)\n",
      "           ^^^^^^^^^^^^^^^^^^^^^^^^^^^^^^^^^^^^^^^^^^^^\n",
      "  File \"/Users/ericwiniecke/.pyenv/versions/3.12.4/envs/cost_cup_env/lib/python3.12/site-packages/psycopg2/__init__.py\", line 122, in connect\n",
      "    conn = _connect(dsn, connection_factory=connection_factory, **kwasync)\n",
      "           ^^^^^^^^^^^^^^^^^^^^^^^^^^^^^^^^^^^^^^^^^^^^^^^^^^^^^^^^^^^^^^^\n",
      "sqlalchemy.exc.OperationalError: (psycopg2.OperationalError) connection to server at \"127.0.0.1\", port 5432 failed: FATAL:  role \"postgresql\" does not exist\n",
      "\n",
      "(Background on this error at: https://sqlalche.me/e/20/e3q8)\n",
      "\n",
      "Script game_plays_processor.py failed with error: Traceback (most recent call last):\n",
      "  File \"/Users/ericwiniecke/.pyenv/versions/3.12.4/envs/cost_cup_env/lib/python3.12/site-packages/sqlalchemy/engine/base.py\", line 146, in __init__\n",
      "    self._dbapi_connection = engine.raw_connection()\n",
      "                             ^^^^^^^^^^^^^^^^^^^^^^^\n",
      "  File \"/Users/ericwiniecke/.pyenv/versions/3.12.4/envs/cost_cup_env/lib/python3.12/site-packages/sqlalchemy/engine/base.py\", line 3300, in raw_connection\n",
      "    return self.pool.connect()\n",
      "           ^^^^^^^^^^^^^^^^^^^\n",
      "  File \"/Users/ericwiniecke/.pyenv/versions/3.12.4/envs/cost_cup_env/lib/python3.12/site-packages/sqlalchemy/pool/base.py\", line 449, in connect\n",
      "    return _ConnectionFairy._checkout(self)\n",
      "           ^^^^^^^^^^^^^^^^^^^^^^^^^^^^^^^^\n",
      "  File \"/Users/ericwiniecke/.pyenv/versions/3.12.4/envs/cost_cup_env/lib/python3.12/site-packages/sqlalchemy/pool/base.py\", line 1263, in _checkout\n",
      "    fairy = _ConnectionRecord.checkout(pool)\n",
      "            ^^^^^^^^^^^^^^^^^^^^^^^^^^^^^^^^\n",
      "  File \"/Users/ericwiniecke/.pyenv/versions/3.12.4/envs/cost_cup_env/lib/python3.12/site-packages/sqlalchemy/pool/base.py\", line 712, in checkout\n",
      "    rec = pool._do_get()\n",
      "          ^^^^^^^^^^^^^^\n",
      "  File \"/Users/ericwiniecke/.pyenv/versions/3.12.4/envs/cost_cup_env/lib/python3.12/site-packages/sqlalchemy/pool/impl.py\", line 179, in _do_get\n",
      "    with util.safe_reraise():\n",
      "  File \"/Users/ericwiniecke/.pyenv/versions/3.12.4/envs/cost_cup_env/lib/python3.12/site-packages/sqlalchemy/util/langhelpers.py\", line 146, in __exit__\n",
      "    raise exc_value.with_traceback(exc_tb)\n",
      "  File \"/Users/ericwiniecke/.pyenv/versions/3.12.4/envs/cost_cup_env/lib/python3.12/site-packages/sqlalchemy/pool/impl.py\", line 177, in _do_get\n",
      "    return self._create_connection()\n",
      "           ^^^^^^^^^^^^^^^^^^^^^^^^^\n",
      "  File \"/Users/ericwiniecke/.pyenv/versions/3.12.4/envs/cost_cup_env/lib/python3.12/site-packages/sqlalchemy/pool/base.py\", line 390, in _create_connection\n",
      "    return _ConnectionRecord(self)\n",
      "           ^^^^^^^^^^^^^^^^^^^^^^^\n",
      "  File \"/Users/ericwiniecke/.pyenv/versions/3.12.4/envs/cost_cup_env/lib/python3.12/site-packages/sqlalchemy/pool/base.py\", line 674, in __init__\n",
      "    self.__connect()\n",
      "  File \"/Users/ericwiniecke/.pyenv/versions/3.12.4/envs/cost_cup_env/lib/python3.12/site-packages/sqlalchemy/pool/base.py\", line 900, in __connect\n",
      "    with util.safe_reraise():\n",
      "  File \"/Users/ericwiniecke/.pyenv/versions/3.12.4/envs/cost_cup_env/lib/python3.12/site-packages/sqlalchemy/util/langhelpers.py\", line 146, in __exit__\n",
      "    raise exc_value.with_traceback(exc_tb)\n",
      "  File \"/Users/ericwiniecke/.pyenv/versions/3.12.4/envs/cost_cup_env/lib/python3.12/site-packages/sqlalchemy/pool/base.py\", line 896, in __connect\n",
      "    self.dbapi_connection = connection = pool._invoke_creator(self)\n",
      "                                         ^^^^^^^^^^^^^^^^^^^^^^^^^^\n",
      "  File \"/Users/ericwiniecke/.pyenv/versions/3.12.4/envs/cost_cup_env/lib/python3.12/site-packages/sqlalchemy/engine/create.py\", line 643, in connect\n",
      "    return dialect.connect(*cargs, **cparams)\n",
      "           ^^^^^^^^^^^^^^^^^^^^^^^^^^^^^^^^^^\n",
      "  File \"/Users/ericwiniecke/.pyenv/versions/3.12.4/envs/cost_cup_env/lib/python3.12/site-packages/sqlalchemy/engine/default.py\", line 620, in connect\n",
      "    return self.loaded_dbapi.connect(*cargs, **cparams)\n",
      "           ^^^^^^^^^^^^^^^^^^^^^^^^^^^^^^^^^^^^^^^^^^^^\n",
      "  File \"/Users/ericwiniecke/.pyenv/versions/3.12.4/envs/cost_cup_env/lib/python3.12/site-packages/psycopg2/__init__.py\", line 122, in connect\n",
      "    conn = _connect(dsn, connection_factory=connection_factory, **kwasync)\n",
      "           ^^^^^^^^^^^^^^^^^^^^^^^^^^^^^^^^^^^^^^^^^^^^^^^^^^^^^^^^^^^^^^^\n",
      "psycopg2.OperationalError: connection to server at \"127.0.0.1\", port 5432 failed: FATAL:  role \"postgresql\" does not exist\n",
      "\n",
      "\n",
      "The above exception was the direct cause of the following exception:\n",
      "\n",
      "Traceback (most recent call last):\n",
      "  File \"/Users/ericwiniecke/Documents/github/cost_cup/game_plays_processor.py\", line 319, in <module>\n",
      "    main()\n",
      "  File \"/Users/ericwiniecke/Documents/github/cost_cup/game_plays_processor.py\", line 303, in main\n",
      "    create_table(engine)\n",
      "  File \"/Users/ericwiniecke/Documents/github/cost_cup/game_plays_processor.py\", line 139, in create_table\n",
      "    metadata.create_all(engine)\n",
      "  File \"/Users/ericwiniecke/.pyenv/versions/3.12.4/envs/cost_cup_env/lib/python3.12/site-packages/sqlalchemy/sql/schema.py\", line 5871, in create_all\n",
      "    bind._run_ddl_visitor(\n",
      "  File \"/Users/ericwiniecke/.pyenv/versions/3.12.4/envs/cost_cup_env/lib/python3.12/site-packages/sqlalchemy/engine/base.py\", line 3250, in _run_ddl_visitor\n",
      "    with self.begin() as conn:\n",
      "  File \"/Users/ericwiniecke/.pyenv/versions/3.12.4/lib/python3.12/contextlib.py\", line 137, in __enter__\n",
      "    return next(self.gen)\n",
      "           ^^^^^^^^^^^^^^\n",
      "  File \"/Users/ericwiniecke/.pyenv/versions/3.12.4/envs/cost_cup_env/lib/python3.12/site-packages/sqlalchemy/engine/base.py\", line 3240, in begin\n",
      "    with self.connect() as conn:\n",
      "         ^^^^^^^^^^^^^^\n",
      "  File \"/Users/ericwiniecke/.pyenv/versions/3.12.4/envs/cost_cup_env/lib/python3.12/site-packages/sqlalchemy/engine/base.py\", line 3276, in connect\n",
      "    return self._connection_cls(self)\n",
      "           ^^^^^^^^^^^^^^^^^^^^^^^^^^\n",
      "  File \"/Users/ericwiniecke/.pyenv/versions/3.12.4/envs/cost_cup_env/lib/python3.12/site-packages/sqlalchemy/engine/base.py\", line 148, in __init__\n",
      "    Connection._handle_dbapi_exception_noconnection(\n",
      "  File \"/Users/ericwiniecke/.pyenv/versions/3.12.4/envs/cost_cup_env/lib/python3.12/site-packages/sqlalchemy/engine/base.py\", line 2440, in _handle_dbapi_exception_noconnection\n",
      "    raise sqlalchemy_exception.with_traceback(exc_info[2]) from e\n",
      "  File \"/Users/ericwiniecke/.pyenv/versions/3.12.4/envs/cost_cup_env/lib/python3.12/site-packages/sqlalchemy/engine/base.py\", line 146, in __init__\n",
      "    self._dbapi_connection = engine.raw_connection()\n",
      "                             ^^^^^^^^^^^^^^^^^^^^^^^\n",
      "  File \"/Users/ericwiniecke/.pyenv/versions/3.12.4/envs/cost_cup_env/lib/python3.12/site-packages/sqlalchemy/engine/base.py\", line 3300, in raw_connection\n",
      "    return self.pool.connect()\n",
      "           ^^^^^^^^^^^^^^^^^^^\n",
      "  File \"/Users/ericwiniecke/.pyenv/versions/3.12.4/envs/cost_cup_env/lib/python3.12/site-packages/sqlalchemy/pool/base.py\", line 449, in connect\n",
      "    return _ConnectionFairy._checkout(self)\n",
      "           ^^^^^^^^^^^^^^^^^^^^^^^^^^^^^^^^\n",
      "  File \"/Users/ericwiniecke/.pyenv/versions/3.12.4/envs/cost_cup_env/lib/python3.12/site-packages/sqlalchemy/pool/base.py\", line 1263, in _checkout\n",
      "    fairy = _ConnectionRecord.checkout(pool)\n",
      "            ^^^^^^^^^^^^^^^^^^^^^^^^^^^^^^^^\n",
      "  File \"/Users/ericwiniecke/.pyenv/versions/3.12.4/envs/cost_cup_env/lib/python3.12/site-packages/sqlalchemy/pool/base.py\", line 712, in checkout\n",
      "    rec = pool._do_get()\n",
      "          ^^^^^^^^^^^^^^\n",
      "  File \"/Users/ericwiniecke/.pyenv/versions/3.12.4/envs/cost_cup_env/lib/python3.12/site-packages/sqlalchemy/pool/impl.py\", line 179, in _do_get\n",
      "    with util.safe_reraise():\n",
      "  File \"/Users/ericwiniecke/.pyenv/versions/3.12.4/envs/cost_cup_env/lib/python3.12/site-packages/sqlalchemy/util/langhelpers.py\", line 146, in __exit__\n",
      "    raise exc_value.with_traceback(exc_tb)\n",
      "  File \"/Users/ericwiniecke/.pyenv/versions/3.12.4/envs/cost_cup_env/lib/python3.12/site-packages/sqlalchemy/pool/impl.py\", line 177, in _do_get\n",
      "    return self._create_connection()\n",
      "           ^^^^^^^^^^^^^^^^^^^^^^^^^\n",
      "  File \"/Users/ericwiniecke/.pyenv/versions/3.12.4/envs/cost_cup_env/lib/python3.12/site-packages/sqlalchemy/pool/base.py\", line 390, in _create_connection\n",
      "    return _ConnectionRecord(self)\n",
      "           ^^^^^^^^^^^^^^^^^^^^^^^\n",
      "  File \"/Users/ericwiniecke/.pyenv/versions/3.12.4/envs/cost_cup_env/lib/python3.12/site-packages/sqlalchemy/pool/base.py\", line 674, in __init__\n",
      "    self.__connect()\n",
      "  File \"/Users/ericwiniecke/.pyenv/versions/3.12.4/envs/cost_cup_env/lib/python3.12/site-packages/sqlalchemy/pool/base.py\", line 900, in __connect\n",
      "    with util.safe_reraise():\n",
      "  File \"/Users/ericwiniecke/.pyenv/versions/3.12.4/envs/cost_cup_env/lib/python3.12/site-packages/sqlalchemy/util/langhelpers.py\", line 146, in __exit__\n",
      "    raise exc_value.with_traceback(exc_tb)\n",
      "  File \"/Users/ericwiniecke/.pyenv/versions/3.12.4/envs/cost_cup_env/lib/python3.12/site-packages/sqlalchemy/pool/base.py\", line 896, in __connect\n",
      "    self.dbapi_connection = connection = pool._invoke_creator(self)\n",
      "                                         ^^^^^^^^^^^^^^^^^^^^^^^^^^\n",
      "  File \"/Users/ericwiniecke/.pyenv/versions/3.12.4/envs/cost_cup_env/lib/python3.12/site-packages/sqlalchemy/engine/create.py\", line 643, in connect\n",
      "    return dialect.connect(*cargs, **cparams)\n",
      "           ^^^^^^^^^^^^^^^^^^^^^^^^^^^^^^^^^^\n",
      "  File \"/Users/ericwiniecke/.pyenv/versions/3.12.4/envs/cost_cup_env/lib/python3.12/site-packages/sqlalchemy/engine/default.py\", line 620, in connect\n",
      "    return self.loaded_dbapi.connect(*cargs, **cparams)\n",
      "           ^^^^^^^^^^^^^^^^^^^^^^^^^^^^^^^^^^^^^^^^^^^^\n",
      "  File \"/Users/ericwiniecke/.pyenv/versions/3.12.4/envs/cost_cup_env/lib/python3.12/site-packages/psycopg2/__init__.py\", line 122, in connect\n",
      "    conn = _connect(dsn, connection_factory=connection_factory, **kwasync)\n",
      "           ^^^^^^^^^^^^^^^^^^^^^^^^^^^^^^^^^^^^^^^^^^^^^^^^^^^^^^^^^^^^^^^\n",
      "sqlalchemy.exc.OperationalError: (psycopg2.OperationalError) connection to server at \"127.0.0.1\", port 5432 failed: FATAL:  role \"postgresql\" does not exist\n",
      "\n",
      "(Background on this error at: https://sqlalche.me/e/20/e3q8)\n",
      "\n",
      "Script player_info_processor.py failed with error: Traceback (most recent call last):\n",
      "  File \"/Users/ericwiniecke/.pyenv/versions/3.12.4/envs/cost_cup_env/lib/python3.12/site-packages/sqlalchemy/engine/base.py\", line 146, in __init__\n",
      "    self._dbapi_connection = engine.raw_connection()\n",
      "                             ^^^^^^^^^^^^^^^^^^^^^^^\n",
      "  File \"/Users/ericwiniecke/.pyenv/versions/3.12.4/envs/cost_cup_env/lib/python3.12/site-packages/sqlalchemy/engine/base.py\", line 3300, in raw_connection\n",
      "    return self.pool.connect()\n",
      "           ^^^^^^^^^^^^^^^^^^^\n",
      "  File \"/Users/ericwiniecke/.pyenv/versions/3.12.4/envs/cost_cup_env/lib/python3.12/site-packages/sqlalchemy/pool/base.py\", line 449, in connect\n",
      "    return _ConnectionFairy._checkout(self)\n",
      "           ^^^^^^^^^^^^^^^^^^^^^^^^^^^^^^^^\n",
      "  File \"/Users/ericwiniecke/.pyenv/versions/3.12.4/envs/cost_cup_env/lib/python3.12/site-packages/sqlalchemy/pool/base.py\", line 1263, in _checkout\n",
      "    fairy = _ConnectionRecord.checkout(pool)\n",
      "            ^^^^^^^^^^^^^^^^^^^^^^^^^^^^^^^^\n",
      "  File \"/Users/ericwiniecke/.pyenv/versions/3.12.4/envs/cost_cup_env/lib/python3.12/site-packages/sqlalchemy/pool/base.py\", line 712, in checkout\n",
      "    rec = pool._do_get()\n",
      "          ^^^^^^^^^^^^^^\n",
      "  File \"/Users/ericwiniecke/.pyenv/versions/3.12.4/envs/cost_cup_env/lib/python3.12/site-packages/sqlalchemy/pool/impl.py\", line 179, in _do_get\n",
      "    with util.safe_reraise():\n",
      "  File \"/Users/ericwiniecke/.pyenv/versions/3.12.4/envs/cost_cup_env/lib/python3.12/site-packages/sqlalchemy/util/langhelpers.py\", line 146, in __exit__\n",
      "    raise exc_value.with_traceback(exc_tb)\n",
      "  File \"/Users/ericwiniecke/.pyenv/versions/3.12.4/envs/cost_cup_env/lib/python3.12/site-packages/sqlalchemy/pool/impl.py\", line 177, in _do_get\n",
      "    return self._create_connection()\n",
      "           ^^^^^^^^^^^^^^^^^^^^^^^^^\n",
      "  File \"/Users/ericwiniecke/.pyenv/versions/3.12.4/envs/cost_cup_env/lib/python3.12/site-packages/sqlalchemy/pool/base.py\", line 390, in _create_connection\n",
      "    return _ConnectionRecord(self)\n",
      "           ^^^^^^^^^^^^^^^^^^^^^^^\n",
      "  File \"/Users/ericwiniecke/.pyenv/versions/3.12.4/envs/cost_cup_env/lib/python3.12/site-packages/sqlalchemy/pool/base.py\", line 674, in __init__\n",
      "    self.__connect()\n",
      "  File \"/Users/ericwiniecke/.pyenv/versions/3.12.4/envs/cost_cup_env/lib/python3.12/site-packages/sqlalchemy/pool/base.py\", line 900, in __connect\n",
      "    with util.safe_reraise():\n",
      "  File \"/Users/ericwiniecke/.pyenv/versions/3.12.4/envs/cost_cup_env/lib/python3.12/site-packages/sqlalchemy/util/langhelpers.py\", line 146, in __exit__\n",
      "    raise exc_value.with_traceback(exc_tb)\n",
      "  File \"/Users/ericwiniecke/.pyenv/versions/3.12.4/envs/cost_cup_env/lib/python3.12/site-packages/sqlalchemy/pool/base.py\", line 896, in __connect\n",
      "    self.dbapi_connection = connection = pool._invoke_creator(self)\n",
      "                                         ^^^^^^^^^^^^^^^^^^^^^^^^^^\n",
      "  File \"/Users/ericwiniecke/.pyenv/versions/3.12.4/envs/cost_cup_env/lib/python3.12/site-packages/sqlalchemy/engine/create.py\", line 643, in connect\n",
      "    return dialect.connect(*cargs, **cparams)\n",
      "           ^^^^^^^^^^^^^^^^^^^^^^^^^^^^^^^^^^\n",
      "  File \"/Users/ericwiniecke/.pyenv/versions/3.12.4/envs/cost_cup_env/lib/python3.12/site-packages/sqlalchemy/engine/default.py\", line 620, in connect\n",
      "    return self.loaded_dbapi.connect(*cargs, **cparams)\n",
      "           ^^^^^^^^^^^^^^^^^^^^^^^^^^^^^^^^^^^^^^^^^^^^\n",
      "  File \"/Users/ericwiniecke/.pyenv/versions/3.12.4/envs/cost_cup_env/lib/python3.12/site-packages/psycopg2/__init__.py\", line 122, in connect\n",
      "    conn = _connect(dsn, connection_factory=connection_factory, **kwasync)\n",
      "           ^^^^^^^^^^^^^^^^^^^^^^^^^^^^^^^^^^^^^^^^^^^^^^^^^^^^^^^^^^^^^^^\n",
      "psycopg2.OperationalError: connection to server at \"127.0.0.1\", port 5432 failed: FATAL:  role \"postgresql\" does not exist\n",
      "\n",
      "\n",
      "The above exception was the direct cause of the following exception:\n",
      "\n",
      "Traceback (most recent call last):\n",
      "  File \"/Users/ericwiniecke/Documents/github/cost_cup/player_info_processor.py\", line 89, in <module>\n",
      "    metadata.create_all(engine)\n",
      "  File \"/Users/ericwiniecke/.pyenv/versions/3.12.4/envs/cost_cup_env/lib/python3.12/site-packages/sqlalchemy/sql/schema.py\", line 5871, in create_all\n",
      "    bind._run_ddl_visitor(\n",
      "  File \"/Users/ericwiniecke/.pyenv/versions/3.12.4/envs/cost_cup_env/lib/python3.12/site-packages/sqlalchemy/engine/base.py\", line 3250, in _run_ddl_visitor\n",
      "    with self.begin() as conn:\n",
      "  File \"/Users/ericwiniecke/.pyenv/versions/3.12.4/lib/python3.12/contextlib.py\", line 137, in __enter__\n",
      "    return next(self.gen)\n",
      "           ^^^^^^^^^^^^^^\n",
      "  File \"/Users/ericwiniecke/.pyenv/versions/3.12.4/envs/cost_cup_env/lib/python3.12/site-packages/sqlalchemy/engine/base.py\", line 3240, in begin\n",
      "    with self.connect() as conn:\n",
      "         ^^^^^^^^^^^^^^\n",
      "  File \"/Users/ericwiniecke/.pyenv/versions/3.12.4/envs/cost_cup_env/lib/python3.12/site-packages/sqlalchemy/engine/base.py\", line 3276, in connect\n",
      "    return self._connection_cls(self)\n",
      "           ^^^^^^^^^^^^^^^^^^^^^^^^^^\n",
      "  File \"/Users/ericwiniecke/.pyenv/versions/3.12.4/envs/cost_cup_env/lib/python3.12/site-packages/sqlalchemy/engine/base.py\", line 148, in __init__\n",
      "    Connection._handle_dbapi_exception_noconnection(\n",
      "  File \"/Users/ericwiniecke/.pyenv/versions/3.12.4/envs/cost_cup_env/lib/python3.12/site-packages/sqlalchemy/engine/base.py\", line 2440, in _handle_dbapi_exception_noconnection\n",
      "    raise sqlalchemy_exception.with_traceback(exc_info[2]) from e\n",
      "  File \"/Users/ericwiniecke/.pyenv/versions/3.12.4/envs/cost_cup_env/lib/python3.12/site-packages/sqlalchemy/engine/base.py\", line 146, in __init__\n",
      "    self._dbapi_connection = engine.raw_connection()\n",
      "                             ^^^^^^^^^^^^^^^^^^^^^^^\n",
      "  File \"/Users/ericwiniecke/.pyenv/versions/3.12.4/envs/cost_cup_env/lib/python3.12/site-packages/sqlalchemy/engine/base.py\", line 3300, in raw_connection\n",
      "    return self.pool.connect()\n",
      "           ^^^^^^^^^^^^^^^^^^^\n",
      "  File \"/Users/ericwiniecke/.pyenv/versions/3.12.4/envs/cost_cup_env/lib/python3.12/site-packages/sqlalchemy/pool/base.py\", line 449, in connect\n",
      "    return _ConnectionFairy._checkout(self)\n",
      "           ^^^^^^^^^^^^^^^^^^^^^^^^^^^^^^^^\n",
      "  File \"/Users/ericwiniecke/.pyenv/versions/3.12.4/envs/cost_cup_env/lib/python3.12/site-packages/sqlalchemy/pool/base.py\", line 1263, in _checkout\n",
      "    fairy = _ConnectionRecord.checkout(pool)\n",
      "            ^^^^^^^^^^^^^^^^^^^^^^^^^^^^^^^^\n",
      "  File \"/Users/ericwiniecke/.pyenv/versions/3.12.4/envs/cost_cup_env/lib/python3.12/site-packages/sqlalchemy/pool/base.py\", line 712, in checkout\n",
      "    rec = pool._do_get()\n",
      "          ^^^^^^^^^^^^^^\n",
      "  File \"/Users/ericwiniecke/.pyenv/versions/3.12.4/envs/cost_cup_env/lib/python3.12/site-packages/sqlalchemy/pool/impl.py\", line 179, in _do_get\n",
      "    with util.safe_reraise():\n",
      "  File \"/Users/ericwiniecke/.pyenv/versions/3.12.4/envs/cost_cup_env/lib/python3.12/site-packages/sqlalchemy/util/langhelpers.py\", line 146, in __exit__\n",
      "    raise exc_value.with_traceback(exc_tb)\n",
      "  File \"/Users/ericwiniecke/.pyenv/versions/3.12.4/envs/cost_cup_env/lib/python3.12/site-packages/sqlalchemy/pool/impl.py\", line 177, in _do_get\n",
      "    return self._create_connection()\n",
      "           ^^^^^^^^^^^^^^^^^^^^^^^^^\n",
      "  File \"/Users/ericwiniecke/.pyenv/versions/3.12.4/envs/cost_cup_env/lib/python3.12/site-packages/sqlalchemy/pool/base.py\", line 390, in _create_connection\n",
      "    return _ConnectionRecord(self)\n",
      "           ^^^^^^^^^^^^^^^^^^^^^^^\n",
      "  File \"/Users/ericwiniecke/.pyenv/versions/3.12.4/envs/cost_cup_env/lib/python3.12/site-packages/sqlalchemy/pool/base.py\", line 674, in __init__\n",
      "    self.__connect()\n",
      "  File \"/Users/ericwiniecke/.pyenv/versions/3.12.4/envs/cost_cup_env/lib/python3.12/site-packages/sqlalchemy/pool/base.py\", line 900, in __connect\n",
      "    with util.safe_reraise():\n",
      "  File \"/Users/ericwiniecke/.pyenv/versions/3.12.4/envs/cost_cup_env/lib/python3.12/site-packages/sqlalchemy/util/langhelpers.py\", line 146, in __exit__\n",
      "    raise exc_value.with_traceback(exc_tb)\n",
      "  File \"/Users/ericwiniecke/.pyenv/versions/3.12.4/envs/cost_cup_env/lib/python3.12/site-packages/sqlalchemy/pool/base.py\", line 896, in __connect\n",
      "    self.dbapi_connection = connection = pool._invoke_creator(self)\n",
      "                                         ^^^^^^^^^^^^^^^^^^^^^^^^^^\n",
      "  File \"/Users/ericwiniecke/.pyenv/versions/3.12.4/envs/cost_cup_env/lib/python3.12/site-packages/sqlalchemy/engine/create.py\", line 643, in connect\n",
      "    return dialect.connect(*cargs, **cparams)\n",
      "           ^^^^^^^^^^^^^^^^^^^^^^^^^^^^^^^^^^\n",
      "  File \"/Users/ericwiniecke/.pyenv/versions/3.12.4/envs/cost_cup_env/lib/python3.12/site-packages/sqlalchemy/engine/default.py\", line 620, in connect\n",
      "    return self.loaded_dbapi.connect(*cargs, **cparams)\n",
      "           ^^^^^^^^^^^^^^^^^^^^^^^^^^^^^^^^^^^^^^^^^^^^\n",
      "  File \"/Users/ericwiniecke/.pyenv/versions/3.12.4/envs/cost_cup_env/lib/python3.12/site-packages/psycopg2/__init__.py\", line 122, in connect\n",
      "    conn = _connect(dsn, connection_factory=connection_factory, **kwasync)\n",
      "           ^^^^^^^^^^^^^^^^^^^^^^^^^^^^^^^^^^^^^^^^^^^^^^^^^^^^^^^^^^^^^^^\n",
      "sqlalchemy.exc.OperationalError: (psycopg2.OperationalError) connection to server at \"127.0.0.1\", port 5432 failed: FATAL:  role \"postgresql\" does not exist\n",
      "\n",
      "(Background on this error at: https://sqlalche.me/e/20/e3q8)\n",
      "\n"
     ]
    }
   ],
   "source": [
    "import logging\n",
    "import subprocess\n",
    "\n",
    "# Configure logging\n",
    "logging.basicConfig(\n",
    "    filename=\"data_processing.log\",\n",
    "    level=logging.INFO,\n",
    "    format=\"%(asctime)s:%(levelname)s:%(message)s\",\n",
    ")\n",
    "\n",
    "def run_script(script_name):\n",
    "    \"\"\"Code to kickoff downloading data from AWS S3 buckets and\n",
    "    inserting data into datatables in the hockey_stats database.\n",
    "    \"\"\"\n",
    "    try:\n",
    "        result = subprocess.run(\n",
    "            [\"python\", script_name], capture_output=True, text=True, check=True\n",
    "        )\n",
    "        logging.info(f\"Output of {script_name}:\\n{result.stdout}\")\n",
    "        if result.stderr:\n",
    "            logging.error(f\"Errors in {script_name}:\\n{result.stderr}\")\n",
    "        print(result.stdout)\n",
    "        print(result.stderr)\n",
    "    except subprocess.CalledProcessError as e:\n",
    "        # This will catch the error if the subprocess fails and check=True is set\n",
    "        logging.error(f\"Script {script_name} failed with error: {e.stderr}\")\n",
    "        print(f\"Script {script_name} failed with error: {e.stderr}\")\n",
    "    except Exception as e:\n",
    "        logging.error(f\"Failed to run {script_name}: {e}\")\n",
    "        print(f\"Failed to run {script_name}: {e}\")\n",
    "\n",
    "def main():\n",
    "    \"\"\"The main event\"\"\"\n",
    "    scripts = [\n",
    "        \"game_processor.py\",\n",
    "        \"game_shifts_processor.py\",\n",
    "        \"game_skater_stats_processor.py\",\n",
    "        \"game_plays_processor.py\",\n",
    "        \"player_info_processor.py\",\n",
    "    ]\n",
    "\n",
    "    for script in scripts:\n",
    "        run_script(script)\n",
    "\n",
    "if __name__ == \"__main__\":\n",
    "    main()\n"
   ]
  },
  {
   "cell_type": "markdown",
   "metadata": {},
   "source": [
    "To run this script in Jupyter, we use the `!` command to execute the script in the notebook environment. This will simulate running the script in the terminal.\n",
    "\n",
    "# Running the main.py script\n",
    "!python main.py\n"
   ]
  },
  {
   "cell_type": "markdown",
   "metadata": {},
   "source": [
    "## 3. Understanding the Logging\n",
    "\n",
    "As `main.py` runs, it logs detailed information to a file named `data_processing.log`. This log file is crucial for debugging and understanding what happened during the execution of the scripts.\n",
    "\n",
    "Let's take a look at the contents of `data_processing.log` to ensure everything ran smoothly.\n"
   ]
  },
  {
   "cell_type": "code",
   "execution_count": null,
   "metadata": {},
   "outputs": [],
   "source": [
    "# Display the contents of the data_processing.log file\n",
    "with open('data_processing.log', 'r') as log_file:\n",
    "    log_content = log_file.read()\n",
    "\n",
    "print(log_content)\n"
   ]
  },
  {
   "cell_type": "markdown",
   "metadata": {},
   "source": [
    "### Analyzing the Log\n",
    "\n",
    "Check for any ERROR messages in the log file. If errors are present, they indicate issues that need to be addressed before moving forward. If everything looks good, the scripts have successfully processed and inserted the data into the database.\n"
   ]
  },
  {
   "cell_type": "markdown",
   "metadata": {},
   "source": [
    "## 4. Verifying the Processed Data\n",
    "\n",
    "After running the `main.py` script, it's important to verify that the data has been correctly processed and inserted into the database. We can do this by querying the database and checking the contents of the tables.\n"
   ]
  },
  {
   "cell_type": "code",
   "execution_count": null,
   "metadata": {},
   "outputs": [],
   "source": [
    "import pandas as pd\n",
    "from sqlalchemy import create_engine\n",
    "\n",
    "# Create a database connection\n",
    "engine = create_engine('your_database_connection_string')\n",
    "\n",
    "# Example query to check the data in one of the tables\n",
    "df = pd.read_sql(\"SELECT * FROM game_skater_stats LIMIT 5;\", engine)\n",
    "\n",
    "# Display the data\n",
    "df.head()\n"
   ]
  },
  {
   "cell_type": "markdown",
   "metadata": {},
   "source": [
    "## 5. Conclusion\n",
    "\n",
    "In this notebook, we successfully ran the `main.py` script, reviewed the logs, and verified that the data was processed and inserted into the database correctly. This sets the stage for more advanced analysis in subsequent parts of the project.\n"
   ]
  }
 ],
 "metadata": {
  "kernelspec": {
   "display_name": "cost_cup_env",
   "language": "python",
   "name": "python3"
  },
  "language_info": {
   "codemirror_mode": {
    "name": "ipython",
    "version": 3
   },
   "file_extension": ".py",
   "mimetype": "text/x-python",
   "name": "python",
   "nbconvert_exporter": "python",
   "pygments_lexer": "ipython3",
   "version": "3.12.4"
  }
 },
 "nbformat": 4,
 "nbformat_minor": 2
}
